[2025-11-01T00:34:26.993+0100] {local_task_job_runner.py:120} INFO - ::group::Pre task execution logs
[2025-11-01T00:34:27.090+0100] {taskinstance.py:2076} INFO - Dependencies all met for dep_context=non-requeueable deps ti=<TaskInstance: avito_producer_every_5min.run_producer manual__2025-10-31T23:31:35+00:00 [queued]>
[2025-11-01T00:34:27.106+0100] {taskinstance.py:2076} INFO - Dependencies all met for dep_context=requeueable deps ti=<TaskInstance: avito_producer_every_5min.run_producer manual__2025-10-31T23:31:35+00:00 [queued]>
[2025-11-01T00:34:27.108+0100] {taskinstance.py:2306} INFO - Starting attempt 2 of 3
[2025-11-01T00:34:27.127+0100] {taskinstance.py:2330} INFO - Executing <Task(BashOperator): run_producer> on 2025-10-31 23:31:35+00:00
[2025-11-01T00:34:27.148+0100] {logging_mixin.py:188} WARNING - /home/***/.local/lib/python3.12/site-packages/***/task/task_runner/standard_task_runner.py:62 DeprecationWarning: This process (pid=315) is multi-threaded, use of fork() may lead to deadlocks in the child.
[2025-11-01T00:34:27.157+0100] {standard_task_runner.py:64} INFO - Started process 316 to run task
[2025-11-01T00:34:27.151+0100] {standard_task_runner.py:90} INFO - Running: ['***', 'tasks', 'run', 'avito_producer_every_5min', 'run_producer', 'manual__2025-10-31T23:31:35+00:00', '--job-id', '95', '--raw', '--subdir', 'DAGS_FOLDER/avito_pipeline.py', '--cfg-path', '/tmp/tmpur3b4skm']
[2025-11-01T00:34:27.163+0100] {standard_task_runner.py:91} INFO - Job 95: Subtask run_producer
[2025-11-01T00:34:27.363+0100] {task_command.py:426} INFO - Running <TaskInstance: avito_producer_every_5min.run_producer manual__2025-10-31T23:31:35+00:00 [running]> on host 840b98c7ef92
[2025-11-01T00:34:27.601+0100] {taskinstance.py:2648} INFO - Exporting env vars: AIRFLOW_CTX_DAG_OWNER='avito' AIRFLOW_CTX_DAG_ID='avito_producer_every_5min' AIRFLOW_CTX_TASK_ID='run_producer' AIRFLOW_CTX_EXECUTION_DATE='2025-10-31T23:31:35+00:00' AIRFLOW_CTX_TRY_NUMBER='2' AIRFLOW_CTX_DAG_RUN_ID='manual__2025-10-31T23:31:35+00:00'
[2025-11-01T00:34:27.603+0100] {taskinstance.py:430} INFO - ::endgroup::
[2025-11-01T00:34:27.646+0100] {subprocess.py:63} INFO - Tmp dir root location: /tmp
[2025-11-01T00:34:27.649+0100] {subprocess.py:75} INFO - Running command: ['/usr/bin/bash', '-c', 'docker exec -i avito-scraper bash -lc "python -m Pipeline.extract.avito_producer --mode louer --pages 1 --limit 10 --bootstrap kafka:9092 --topic realestate.avito.raw"']
[2025-11-01T00:34:27.672+0100] {subprocess.py:86} INFO - Output:
[2025-11-01T00:34:28.098+0100] {subprocess.py:93} INFO - /usr/local/bin/python: No module named Pipeline.extract.avito_producer
[2025-11-01T00:34:28.115+0100] {subprocess.py:97} INFO - Command exited with return code 1
[2025-11-01T00:34:28.117+0100] {taskinstance.py:441} INFO - ::group::Post task execution logs
[2025-11-01T00:34:28.136+0100] {taskinstance.py:2905} ERROR - Task failed with exception
Traceback (most recent call last):
  File "/home/airflow/.local/lib/python3.12/site-packages/airflow/models/taskinstance.py", line 465, in _execute_task
    result = _execute_callable(context=context, **execute_callable_kwargs)
             ^^^^^^^^^^^^^^^^^^^^^^^^^^^^^^^^^^^^^^^^^^^^^^^^^^^^^^^^^^^^^
  File "/home/airflow/.local/lib/python3.12/site-packages/airflow/models/taskinstance.py", line 432, in _execute_callable
    return execute_callable(context=context, **execute_callable_kwargs)
           ^^^^^^^^^^^^^^^^^^^^^^^^^^^^^^^^^^^^^^^^^^^^^^^^^^^^^^^^^^^^
  File "/home/airflow/.local/lib/python3.12/site-packages/airflow/models/baseoperator.py", line 401, in wrapper
    return func(self, *args, **kwargs)
           ^^^^^^^^^^^^^^^^^^^^^^^^^^^
  File "/home/airflow/.local/lib/python3.12/site-packages/airflow/operators/bash.py", line 243, in execute
    raise AirflowException(
airflow.exceptions.AirflowException: Bash command failed. The command returned a non-zero exit code 1.
[2025-11-01T00:34:28.147+0100] {taskinstance.py:1206} INFO - Marking task as UP_FOR_RETRY. dag_id=avito_producer_every_5min, task_id=run_producer, run_id=manual__2025-10-31T23:31:35+00:00, execution_date=20251031T233135, start_date=20251031T233427, end_date=20251031T233428
[2025-11-01T00:34:28.160+0100] {standard_task_runner.py:110} ERROR - Failed to execute job 95 for task run_producer (Bash command failed. The command returned a non-zero exit code 1.; 316)
[2025-11-01T00:34:28.178+0100] {local_task_job_runner.py:243} INFO - Task exited with return code 1
[2025-11-01T00:34:28.201+0100] {taskinstance.py:3503} INFO - 0 downstream tasks scheduled from follow-on schedule check
[2025-11-01T00:34:28.204+0100] {local_task_job_runner.py:222} INFO - ::endgroup::
